<?xml version="1.0" encoding="utf-8"?>
<!-- This URDF was automatically created by SolidWorks to URDF Exporter! Originally created by Stephen Brawner (brawner@gmail.com) 
     Commit Version: 1.6.0-4-g7f85cfe  Build Version: 1.6.7995.38578
     For more information, please see http://wiki.ros.org/sw_urdf_exporter -->
<robot
  name="RCV8">
    <mujoco>
    <compiler 
      meshdir="../meshes" 
      balanceinertia="true" 
      discardvisual="false" />
  </mujoco>
  <link
    name="base_link">
    <inertial>
      <origin
        xyz="0.0080583 0.0005398 0.0606645"
        rpy="0 0 0" />
      <mass
        value="6" />
      <inertia
        ixx="0.0352207"
        ixy="-0.0007207"
        ixz="-0.0019191"
        iyy="0.0728560"
        iyz="0.0000191"
        izz="0.0856750" />
    </inertial>
    <visual>
      <origin
        xyz="0 0 0"
        rpy="0 0 0" />
      <geometry>
        <mesh
          filename="..//meshes/base_link.STL" />
      </geometry>
      <material
        name="">
        <color
          rgba="1 1 1 1" />
      </material>
    </visual>
    <collision>
      <origin
        xyz="0 0 0.04290"
        rpy="0 0 0" />
      <geometry>
        <box
          size="0.34 0.20000 0.15980" />
      </geometry>
    </collision>
    
  </link>
  <link
    name="FL">
    <inertial>
      <origin
        xyz="-0.0117255 -0.0121303 -0.0000462"
        rpy="0 0 0" />
      <mass
        value="0.75" />
      <inertia
        ixx="0.0001882"
        ixy="0.0000377"
        ixz="0.0000005"
        iyy="0.0003670"
        iyz="-0.0000002"
        izz="0.0002544" />
    </inertial>
    <visual>
      <origin
        xyz="0 0 0"
        rpy="0 0 0" />
      <geometry>
        <mesh
          filename="..//meshes/FL.STL" />
      </geometry>
      <material
        name="">
        <color
          rgba="1 1 1 1" />
      </material>
    </visual>
  </link>
  <joint
    name="FL_hip_joint"
    type="revolute">
    <origin
      xyz="0.23285 0.0625 0.05425"
      rpy="0 0 0" />
    <parent
      link="base_link" />
    <child
      link="FL" />
    <axis
      xyz="1 0 0" />
    <limit
      lower="-1.05"
      upper="1.05"
      effort="18.0"
      velocity="30" />
  </joint>
  <link
    name="FL_thigh">
    <inertial>
      <origin
        xyz="-0.0009008 -0.0236371 -0.0344781"
        rpy="0 0 0" />
      <mass
        value="0.85" />
      <inertia
        ixx="0.0050481"
        ixy="0.0000052"
        ixz="-0.0003188"
        iyy="0.0048560"
        iyz="0.0007267"
        izz="0.0010600" />
    </inertial>
    <visual>
      <origin
        xyz="0 0 0"
        rpy="0 0 0" />
      <geometry>
        <mesh
          filename="..//meshes/FL_thigh.STL" />
      </geometry>
      <material
        name="">
        <color
          rgba="1 1 1 1" />
      </material>
    </visual>
    <collision>
      <origin
        xyz="-0.003 -0.008 -0.002"
        rpy="1.57079632679 0 0" />
      <geometry>
        <cylinder
          radius="0.0450"
          length="0.05" />
      </geometry>
    </collision>
    <collision>
      <origin
        xyz="-0.0220 0 -0.1400"
        rpy="0 0 0" />
      <geometry>
        <cylinder
          radius="0.0205"
          length="0.1620" />
      </geometry>
    </collision>
  </link>
  <joint
    name="FL_thigh_joint"
    type="revolute">
    <origin
      xyz="0 0.0904 0"
      rpy="0 0 0" />
    <parent
      link="FL" />
    <child
      link="FL_thigh" />
    <axis
      xyz="0 1 0" />
    <limit
      lower="-1.57"
      upper="3.49"
      effort="18.0"
      velocity="30" />
  </joint>
  <link
    name="FL_calf">
    <inertial>
      <origin
        xyz="0.0038942 0.0007975 -0.1721584"
        rpy="0 0 0" />
      <mass
        value="0.1" />
      <inertia
        ixx="0.0017683"
        ixy="0.0000017"
        ixz="-0.0000664"
        iyy="0.0017957"
        iyz="0.0000138"
        izz="0.0000409" />
    </inertial>
    <visual>
      <origin
        xyz="0 0 0"
        rpy="0 0 0" />
      <geometry>
        <mesh
          filename="..//meshes/FL_calf.STL" />
      </geometry>
      <material
        name="">
        <color
          rgba="1 1 1 1" />
      </material>
    </visual>
    <collision>
      <origin
        xyz="0.0155 0 -0.1250"
        rpy="0 0 0" />
      <geometry>
        <cylinder
          radius="0.0125"
          length="0.2500" />
      </geometry>
    </collision>
  </link>
  <joint
    name="FL_calf_joint"
    type="revolute">
    <origin
      xyz="0 0 -0.26"
      rpy="0 0 0" />
    <parent
      link="FL_thigh" />
    <child
      link="FL_calf" />
    <axis
      xyz="0 1 0" />
    <limit
      lower="-2.72"
      upper="-0.84"
      effort="18.0"
      velocity="30" />
  </joint>
  <link
    name="FL_foot">
    <inertial>
      <origin
        xyz="0.0048384 0.0002654 0.010366"
        rpy="0 0 0" />
      <mass
        value="0.05" />
      <inertia
        ixx="0.0000122"
        ixy="0.0000000"
        ixz="-0.0000006"
        iyy="0.0000137"
        iyz="-0.0000001"
        izz="0.0000112" />
    </inertial>
    <visual>
      <origin
        xyz="0 0 0"
        rpy="0 0 0" />
      <geometry>
        <mesh
          filename="..//meshes/FL_foot.STL" />
      </geometry>
      <material
        name="">
        <color
          rgba="0.79216 0.81961 0.93333 1" />
      </material>
    </visual>
    <collision>
      <origin
        xyz="0.0043 0.0002 0.0050"
        rpy="0 0 0" />
      <geometry>
        <sphere
          radius="0.0202" />
      </geometry>
    </collision>
    <collision>
      <origin
        xyz="0.0205 0.0002 0.035"
        rpy="0 0 0" />
      <geometry>
        <box
          size="0.027 0.020 0.015" />
      </geometry>
    </collision>
  </link>
  <joint
    name="FL_foot_joint"
    type="fixed"
    dont_collapse="true">
    <origin
      xyz="-0.014048 0 -0.29437"
      rpy="0 0 0" />
    <parent
      link="FL_calf" />
    <child
      link="FL_foot" />
    <axis
      xyz="0 0 0" />
  </joint>
  <link
    name="FR">
    <inertial>
      <origin
        xyz="-0.0117255 0.0121303 0.0000462"
        rpy="0 0 0" />
      <mass
        value="0.75" />
      <inertia
        ixx="0.0001882"
        ixy="-0.0000377"
        ixz="-0.0000005"
        iyy="0.0003670"
        iyz="-0.0000002"
        izz="0.0002544" />
    </inertial>
    <visual>
      <origin
        xyz="0 0 0"
        rpy="0 0 0" />
      <geometry>
        <mesh
          filename="..//meshes/FR.STL" />
      </geometry>
      <material
        name="">
        <color
          rgba="1 1 1 1" />
      </material>
    </visual>
  </link>
  <joint
    name="FR_hip_joint"
    type="revolute">
    <origin
      xyz="0.23285 -0.0625 0.05425"
      rpy="0 0 0" />
    <parent
      link="base_link" />
    <child
      link="FR" />
    <axis
      xyz="1 0 0" />
    <limit
      lower="-1.05"
      upper="1.05"
      effort="18.0"
      velocity="30" />
  </joint>
  <link
    name="FR_thigh">
    <inertial>
      <origin
        xyz="-0.0009016 0.0236316 -0.0344912"
        rpy="0 0 0" />
      <mass
        value="0.85" />
      <inertia
        ixx="0.0050487"
        ixy="-0.0000052"
        ixz="-0.0003188"
        iyy="0.0048566"
        iyz="-0.0007267"
        izz="0.0010601" />
    </inertial>
    <visual>
      <origin
        xyz="0 0 0"
        rpy="0 0 0" />
      <geometry>
        <mesh
          filename="..//meshes/FR_thigh.STL" />
      </geometry>
      <material
        name="">
        <color
          rgba="1 1 1 1" />
      </material>
    </visual>
    <collision>
      <origin
        xyz="-0.003 0.008 -0.002"
        rpy="1.57079632679 0 0" />
      <geometry>
        <cylinder
          radius="0.0450"
          length="0.05" />
      </geometry>
    </collision>
    <collision>
      <origin
        xyz="-0.0220 0 -0.1400"
        rpy="0 0 0" />
      <geometry>
        <cylinder
          radius="0.0205"
          length="0.1620" />
      </geometry>
    </collision>
  </link>
  <joint
    name="FR_thigh_joint"
    type="revolute">
    <origin
      xyz="0 -0.0904 0"
      rpy="0 0 0" />
    <parent
      link="FR" />
    <child
      link="FR_thigh" />
    <axis
      xyz="0 1 0" />
    <limit
      lower="-1.57"
      upper="3.49"
      effort="18.0"
      velocity="30" />
  </joint>
  <link
    name="FR_calf">
    <inertial>
      <origin
        xyz="0.0038942 0.0007975 -0.1721584"
        rpy="0 0 0" />
      <mass
        value="0.1" />
      <inertia
        ixx="0.0017683"
        ixy="0.0000017"
        ixz="-0.0000664"
        iyy="0.0017957"
        iyz="0.0000138"
        izz="0.0000409" />
    </inertial>
    <visual>
      <origin
        xyz="0 0 0"
        rpy="0 0 0" />
      <geometry>
        <mesh
          filename="..//meshes/FR_calf.STL" />
      </geometry>
      <material
        name="">
        <color
          rgba="1 1 1 1" />
      </material>
    </visual>
    <collision>
      <origin
        xyz="0.0155 0 -0.1250"
        rpy="0 0 0" />
      <geometry>
        <cylinder
          radius="0.0125"
          length="0.2500" />
      </geometry>
    </collision>
  </link>
  <joint
    name="FR_calf_joint"
    type="revolute">
    <origin
      xyz="0 0 -0.26"
      rpy="0 0 0" />
    <parent
      link="FR_thigh" />
    <child
      link="FR_calf" />
    <axis
      xyz="0 1 0" />
    <limit
      lower="-2.72"
      upper="-0.84"
      effort="18.0"
      velocity="30" />
  </joint>
  <link
    name="FR_foot">
    <inertial>
      <origin
        xyz="0.0048382 -0.0002654 0.010367"
        rpy="0 0 0" />
      <mass
        value="0.05" />
      <inertia
        ixx="0.0000122"
        ixy="0.0000000"
        ixz="-0.0000006"
        iyy="0.0000137"
        iyz="0.0000001"
        izz="0.0000112" />
    </inertial>
    <visual>
      <origin
        xyz="0 0 0"
        rpy="0 0 0" />
      <geometry>
        <mesh
          filename="..//meshes/FR_foot.STL" />
      </geometry>
      <material
        name="">
        <color
          rgba="0.79216 0.81961 0.93333 1" />
      </material>
    </visual>
    <collision>
      <origin
        xyz="0.0043 -0.0002 0.0050"
        rpy="0 0 0" />
      <geometry>
        <sphere
          radius="0.0202" />
      </geometry>
    </collision>
    <collision>
      <origin
        xyz="0.0205 -0.0002 0.035"
        rpy="0 0 0" />
      <geometry>
        <box
          size="0.027 0.020 0.015" />
      </geometry>
    </collision>
  </link>
  <joint
    name="FR_foot_joint"
    type="fixed"
    dont_collapse="true">
    <origin
      xyz="-0.014048 0 -0.29437"
      rpy="0 0 0" />
    <parent
      link="FR_calf" />
    <child
      link="FR_foot" />
    <axis
      xyz="0 0 0" />
  </joint>
  <link
    name="RL">
    <inertial>
      <origin
        xyz="0.0117255 -0.0121303 0.0000462"
        rpy="0 0 0" />
      <mass
        value="0.75" />
      <inertia
        ixx="0.0001882"
        ixy="-0.0000377"
        ixz="0.0000005"
        iyy="0.0003670"
        iyz="0.0000002"
        izz="0.0002544" />
    </inertial>
    <visual>
      <origin
        xyz="0 0 0"
        rpy="0 0 0" />
      <geometry>
        <mesh
          filename="..//meshes/RL.STL" />
      </geometry>
      <material
        name="">
        <color
          rgba="1 1 1 1" />
      </material>
    </visual>
  </link>
  <joint
    name="RL_hip_joint"
    type="revolute">
    <origin
      xyz="-0.23285 0.0625 0.05425"
      rpy="0 0 0" />
    <parent
      link="base_link" />
    <child
      link="RL" />
    <axis
      xyz="1 0 0" />
    <limit
      lower="-1.05"
      upper="1.05"
      effort="18.0"
      velocity="30" />
  </joint>
  <link
    name="RL_thigh">
    <inertial>
      <origin
        xyz="-0.0009008 -0.0236371 -0.0344781"
        rpy="0 0 0" />
      <mass
        value="0.85" />
      <inertia
        ixx="0.0050481"
        ixy="0.0000052"
        ixz="-0.0003188"
        iyy="0.0048560"
        iyz="0.0007267"
        izz="0.0010600" />
    </inertial>
    <visual>
      <origin
        xyz="0 0 0"
        rpy="0 0 0" />
      <geometry>
        <mesh
          filename="..//meshes/RL_thigh.STL" />
      </geometry>
      <material
        name="">
        <color
          rgba="1 1 1 1" />
      </material>
    </visual>
    <collision>
      <origin
        xyz="-0.003 -0.008 -0.002"
        rpy="1.57079632679 0 0" />
      <geometry>
        <cylinder
          radius="0.0450"
          length="0.05" />
      </geometry>
    </collision>
    <collision>
      <origin
        xyz="-0.0220 0 -0.1400"
        rpy="0 0 0" />
      <geometry>
        <cylinder
          radius="0.0205"
          length="0.1620" />
      </geometry>
    </collision>
  </link>
  <joint
    name="RL_thigh_joint"
    type="revolute">
    <origin
      xyz="0 0.0904 0"
      rpy="0 0 0" />
    <parent
      link="RL" />
    <child
      link="RL_thigh" />
    <axis
      xyz="0 1 0" />
    <limit
      lower="-0.52"
      upper="4.54"
      effort="18.0"
      velocity="30" />
  </joint>
  <link
    name="RL_calf">
    <inertial>
      <origin
        xyz="0.0038942 0.0007975 -0.1721584"
        rpy="0 0 0" />
      <mass
        value="0.1" />
      <inertia
        ixx="0.0017683"
        ixy="0.0000017"
        ixz="-0.0000664"
        iyy="0.0017957"
        iyz="0.0000138"
        izz="0.0000409" />
    </inertial>
    <visual>
      <origin
        xyz="0 0 0"
        rpy="0 0 0" />
      <geometry>
        <mesh
          filename="..//meshes/RL_calf.STL" />
      </geometry>
      <material
        name="">
        <color
          rgba="1 1 1 1" />
      </material>
    </visual>
    <collision>
      <origin
        xyz="0.0155 0 -0.1250"
        rpy="0 0 0" />
      <geometry>
        <cylinder
          radius="0.0125"
          length="0.2500" />
      </geometry>
    </collision>
  </link>
  <joint
    name="RL_calf_joint"
    type="revolute">
    <origin
      xyz="0 0 -0.26"
      rpy="0 0 0" />
    <parent
      link="RL_thigh" />
    <child
      link="RL_calf" />
    <axis
      xyz="0 1 0" />
    <limit
      lower="-2.72"
      upper="-0.84"
      effort="18.0"
      velocity="30" />
  </joint>
  <link
    name="RL_foot">
    <inertial>
      <origin
        xyz="0.0048384 0.0002654 0.010366"
        rpy="0 0 0" />
      <mass
        value="0.05" />
      <inertia
        ixx="0.0000122"
        ixy="0.0000000"
        ixz="-0.0000006"
        iyy="0.0000137"
        iyz="-0.0000001"
        izz="0.0000112" />
    </inertial>
    <visual>
      <origin
        xyz="0 0 0"
        rpy="0 0 0" />
      <geometry>
        <mesh
          filename="..//meshes/RL_foot.STL" />
      </geometry>
      <material
        name="">
        <color
          rgba="0.79216 0.81961 0.93333 1" />
      </material>
    </visual>
    <collision>
      <origin
        xyz="0.0043 0.0002 0.0050"
        rpy="0 0 0" />
      <geometry>
        <sphere
          radius="0.0206" />
      </geometry>
    </collision>
    <collision>
      <origin
        xyz="0.0205 0.0002 0.035"
        rpy="0 0 0" />
      <geometry>
        <box
          size="0.027 0.020 0.015" />
      </geometry>
    </collision>
  </link>
  <joint
    name="RL_foot_joint"
    type="fixed"
    dont_collapse="true">
    <origin
      xyz="-0.0140482260590471 0 -0.294374371435754"
      rpy="0 0 0" />
    <parent
      link="RL_calf" />
    <child
      link="RL_foot" />
    <axis
      xyz="0 0 0" />
  </joint>
  <link
    name="RR">
    <inertial>
      <origin
        xyz="0.0117255 0.0121303 -0.0000462"
        rpy="0 0 0" />
      <mass
        value="0.75" />
      <inertia
        ixx="0.0001882"
        ixy="0.0000377"
        ixz="-0.0000005"
        iyy="0.0003670"
        iyz="0.0000002"
        izz="0.0002544" />
    </inertial>
    <visual>
      <origin
        xyz="0 0 0"
        rpy="0 0 0" />
      <geometry>
        <mesh
          filename="..//meshes/RR.STL" />
      </geometry>
      <material
        name="">
        <color
          rgba="1 1 1 1" />
      </material>
    </visual>
  </link>
  <joint
    name="RR_hip_joint"
    type="revolute">
    <origin
      xyz="-0.23285 -0.0625 0.05425"
      rpy="0 0 0" />
    <parent
      link="base_link" />
    <child
      link="RR" />
    <axis
      xyz="1 0 0" />
    <limit
      lower="-1.05"
      upper="1.05"
      effort="18.0"
      velocity="30" />
  </joint>
  <link
    name="RR_thigh">
    <inertial>
      <origin
        xyz="-0.0009016 0.0236316 -0.0344912"
        rpy="0 0 0" />
      <mass
        value="0.85" />
      <inertia
        ixx="0.0050487"
        ixy="-0.0000052"
        ixz="-0.0003188"
        iyy="0.0048566"
        iyz="-0.0007267"
        izz="0.0010601" />
    </inertial>
    <visual>
      <origin
        xyz="0 0 0"
        rpy="0 0 0" />
      <geometry>
        <mesh
          filename="..//meshes/RR_thigh.STL" />
      </geometry>
      <material
        name="">
        <color
          rgba="1 1 1 1" />
      </material>
    </visual>
    <collision>
      <origin
        xyz="-0.003 0.008 -0.002"
        rpy="1.57079632679 0 0" />
      <geometry>
        <cylinder
          radius="0.0450"
          length="0.05" />
      </geometry>
    </collision>
    <collision>
      <origin
        xyz="-0.0220 0 -0.1400"
        rpy="0 0 0" />
      <geometry>
        <cylinder
          radius="0.0205"
          length="0.1620" />
      </geometry>
    </collision>
  </link>
  <joint
    name="RR_thigh_joint"
    type="revolute">
    <origin
      xyz="0 -0.0904 0"
      rpy="0 0 0" />
    <parent
      link="RR" />
    <child
      link="RR_thigh" />
    <axis
      xyz="0 1 0" />
    <limit
      lower="-0.52"
      upper="4.54"
      effort="18.0"
      velocity="30" />
  </joint>
  <link
    name="RR_calf">
    <inertial>
      <origin
        xyz="0.0038942 0.0007975 -0.1721584"
        rpy="0 0 0" />
      <mass
        value="0.1" />
      <inertia
        ixx="0.0017683"
        ixy="0.0000017"
        ixz="-0.0000664"
        iyy="0.0017957"
        iyz="0.0000138"
        izz="0.0000409" />
    </inertial>
    <visual>
      <origin
        xyz="0 0 0"
        rpy="0 0 0" />
      <geometry>
        <mesh
          filename="..//meshes/RR_calf.STL" />
      </geometry>
      <material
        name="">
        <color
          rgba="1 1 1 1" />
      </material>
    </visual>
    <collision>
      <origin
        xyz="0.0155 0 -0.1250"
        rpy="0 0 0" />
      <geometry>
        <cylinder
          radius="0.0125"
          length="0.2500" />
      </geometry>
    </collision>
  </link>
  <joint
    name="RR_calf_joint"
    type="revolute">
    <origin
      xyz="0 0 -0.26"
      rpy="0 0 0" />
    <parent
      link="RR_thigh" />
    <child
      link="RR_calf" />
    <axis
      xyz="0 1 0" />
    <limit
      lower="-2.72"
      upper="-0.84"
      effort="18.0"
      velocity="30" />
  </joint>
  <link
    name="RR_foot">
    <inertial>
      <origin
        xyz="0.0048382 -0.00026536 0.010367"
        rpy="0 0 0" />
      <mass
        value="0.05" />
      <inertia
        ixx="0.0000122"
        ixy="0.0000000"
        ixz="-0.0000006"
        iyy="0.0000137"
        iyz="0.0000001"
        izz="0.0000112" />
    </inertial>
    <visual>
      <origin
        xyz="0 0 0"
        rpy="0 0 0" />
      <geometry>
        <mesh
          filename="..//meshes/RR_foot.STL" />
      </geometry>
      <material
        name="">
        <color
          rgba="0.79216 0.81961 0.93333 1" />
      </material>
    </visual>
    <collision>
      <origin
        xyz="0.0043 -0.0002 0.0050"
        rpy="0 0 0" />
      <geometry>
        <sphere
          radius="0.0200" />
      </geometry>
    </collision>
    <collision>
      <origin
        xyz="0.0205 -0.0002 0.035"
        rpy="0 0 0" />
      <geometry>
        <box
          size="0.027 0.020 0.015" />
      </geometry>
    </collision>
  </link>
  <joint
    name="RR_foot_joint"
    type="fixed"
    dont_collapse="true">
    <origin
      xyz="-0.014048 0 -0.29437"
      rpy="0 0 0" />
    <parent
      link="RR_calf" />
    <child
      link="RR_foot" />
    <axis
      xyz="0 0 0" />
  </joint>
</robot>
